/var/spool/slurmd/job4357316/slurm_script: line 2: SBATCH: command not found
/var/spool/slurmd/job4357316/slurm_script: line 3: SBATCH: command not found
/var/spool/slurmd/job4357316/slurm_script: line 4: SBATCH: command not found
/var/spool/slurmd/job4357316/slurm_script: line 5: SBATCH: command not found
/var/spool/slurmd/job4357316/slurm_script: line 6: SBATCH: command not found
/var/spool/slurmd/job4357316/slurm_script: line 7: SBATCH: command not found
/var/spool/slurmd/job4357316/slurm_script: line 8: SBATCH: command not found
/var/spool/slurmd/job4357316/slurm_script: line 9: SBATCH: command not found
/var/spool/slurmd/job4357316/slurm_script: line 10: SBATCH: command not found
Environment activated: 
Performing tests...
Running tests for test/test_groupby.py with argument (if needed): Pregnancies...
Error running subprocess for test/test_groupby.py with ../data/benchmarking_data_varying_size/benchmarking_data_10000.csv:
Traceback (most recent call last):
  File "/u/erg3kp/cylonplus/parallelpandas_testing/test/test_groupby.py", line 2, in <module>
    from parallel_pandas import ParallelPandas
  File "/u/erg3kp/.local/lib/python3.10/site-packages/parallel_pandas/__init__.py", line 1, in <module>
    from .main import ParallelPandas
  File "/u/erg3kp/.local/lib/python3.10/site-packages/parallel_pandas/main.py", line 3, in <module>
    from .core import series_parallelize_apply
  File "/u/erg3kp/.local/lib/python3.10/site-packages/parallel_pandas/core/__init__.py", line 4, in <module>
    from .parallel_dataframe import parallelize_apply
  File "/u/erg3kp/.local/lib/python3.10/site-packages/parallel_pandas/core/parallel_dataframe.py", line 22, in <module>
    from ._numba import _do_parallel_corr
  File "/u/erg3kp/.local/lib/python3.10/site-packages/parallel_pandas/core/_numba.py", line 4, in <module>
    from numba import njit, prange
  File "/sw/ubuntu-22.04/anaconda3/current/lib/python3.10/site-packages/numba/__init__.py", line 42, in <module>
    from numba.np.ufunc import (vectorize, guvectorize, threading_layer,
  File "/sw/ubuntu-22.04/anaconda3/current/lib/python3.10/site-packages/numba/np/ufunc/__init__.py", line 3, in <module>
    from numba.np.ufunc.decorators import Vectorize, GUVectorize, vectorize, guvectorize
  File "/sw/ubuntu-22.04/anaconda3/current/lib/python3.10/site-packages/numba/np/ufunc/decorators.py", line 3, in <module>
    from numba.np.ufunc import _internal
SystemError: initialization of _internal failed without raising an exception

Error running subprocess for test/test_groupby.py with ../data/benchmarking_data_varying_size/benchmarking_data_500000.csv:
Traceback (most recent call last):
  File "/u/erg3kp/cylonplus/parallelpandas_testing/test/test_groupby.py", line 2, in <module>
    from parallel_pandas import ParallelPandas
  File "/u/erg3kp/.local/lib/python3.10/site-packages/parallel_pandas/__init__.py", line 1, in <module>
    from .main import ParallelPandas
  File "/u/erg3kp/.local/lib/python3.10/site-packages/parallel_pandas/main.py", line 3, in <module>
    from .core import series_parallelize_apply
  File "/u/erg3kp/.local/lib/python3.10/site-packages/parallel_pandas/core/__init__.py", line 4, in <module>
    from .parallel_dataframe import parallelize_apply
  File "/u/erg3kp/.local/lib/python3.10/site-packages/parallel_pandas/core/parallel_dataframe.py", line 22, in <module>
    from ._numba import _do_parallel_corr
  File "/u/erg3kp/.local/lib/python3.10/site-packages/parallel_pandas/core/_numba.py", line 4, in <module>
    from numba import njit, prange
  File "/sw/ubuntu-22.04/anaconda3/current/lib/python3.10/site-packages/numba/__init__.py", line 42, in <module>
    from numba.np.ufunc import (vectorize, guvectorize, threading_layer,
  File "/sw/ubuntu-22.04/anaconda3/current/lib/python3.10/site-packages/numba/np/ufunc/__init__.py", line 3, in <module>
    from numba.np.ufunc.decorators import Vectorize, GUVectorize, vectorize, guvectorize
  File "/sw/ubuntu-22.04/anaconda3/current/lib/python3.10/site-packages/numba/np/ufunc/decorators.py", line 3, in <module>
    from numba.np.ufunc import _internal
SystemError: initialization of _internal failed without raising an exception

Error running subprocess for test/test_groupby.py with ../data/benchmarking_data_varying_size/benchmarking_data_1000000.csv:
Traceback (most recent call last):
  File "/u/erg3kp/cylonplus/parallelpandas_testing/test/test_groupby.py", line 2, in <module>
    from parallel_pandas import ParallelPandas
  File "/u/erg3kp/.local/lib/python3.10/site-packages/parallel_pandas/__init__.py", line 1, in <module>
    from .main import ParallelPandas
  File "/u/erg3kp/.local/lib/python3.10/site-packages/parallel_pandas/main.py", line 3, in <module>
    from .core import series_parallelize_apply
  File "/u/erg3kp/.local/lib/python3.10/site-packages/parallel_pandas/core/__init__.py", line 4, in <module>
    from .parallel_dataframe import parallelize_apply
  File "/u/erg3kp/.local/lib/python3.10/site-packages/parallel_pandas/core/parallel_dataframe.py", line 22, in <module>
    from ._numba import _do_parallel_corr
  File "/u/erg3kp/.local/lib/python3.10/site-packages/parallel_pandas/core/_numba.py", line 4, in <module>
    from numba import njit, prange
  File "/sw/ubuntu-22.04/anaconda3/current/lib/python3.10/site-packages/numba/__init__.py", line 42, in <module>
    from numba.np.ufunc import (vectorize, guvectorize, threading_layer,
  File "/sw/ubuntu-22.04/anaconda3/current/lib/python3.10/site-packages/numba/np/ufunc/__init__.py", line 3, in <module>
    from numba.np.ufunc.decorators import Vectorize, GUVectorize, vectorize, guvectorize
  File "/sw/ubuntu-22.04/anaconda3/current/lib/python3.10/site-packages/numba/np/ufunc/decorators.py", line 3, in <module>
    from numba.np.ufunc import _internal
SystemError: initialization of _internal failed without raising an exception

Error running subprocess for test/test_groupby.py with ../data/benchmarking_data_varying_size/benchmarking_data_2500000.csv:
Traceback (most recent call last):
  File "/u/erg3kp/cylonplus/parallelpandas_testing/test/test_groupby.py", line 2, in <module>
    from parallel_pandas import ParallelPandas
  File "/u/erg3kp/.local/lib/python3.10/site-packages/parallel_pandas/__init__.py", line 1, in <module>
    from .main import ParallelPandas
  File "/u/erg3kp/.local/lib/python3.10/site-packages/parallel_pandas/main.py", line 3, in <module>
    from .core import series_parallelize_apply
  File "/u/erg3kp/.local/lib/python3.10/site-packages/parallel_pandas/core/__init__.py", line 4, in <module>
    from .parallel_dataframe import parallelize_apply
  File "/u/erg3kp/.local/lib/python3.10/site-packages/parallel_pandas/core/parallel_dataframe.py", line 22, in <module>
    from ._numba import _do_parallel_corr
  File "/u/erg3kp/.local/lib/python3.10/site-packages/parallel_pandas/core/_numba.py", line 4, in <module>
    from numba import njit, prange
  File "/sw/ubuntu-22.04/anaconda3/current/lib/python3.10/site-packages/numba/__init__.py", line 42, in <module>
    from numba.np.ufunc import (vectorize, guvectorize, threading_layer,
  File "/sw/ubuntu-22.04/anaconda3/current/lib/python3.10/site-packages/numba/np/ufunc/__init__.py", line 3, in <module>
    from numba.np.ufunc.decorators import Vectorize, GUVectorize, vectorize, guvectorize
  File "/sw/ubuntu-22.04/anaconda3/current/lib/python3.10/site-packages/numba/np/ufunc/decorators.py", line 3, in <module>
    from numba.np.ufunc import _internal
SystemError: initialization of _internal failed without raising an exception

Error running subprocess for test/test_groupby.py with ../data/benchmarking_data_varying_size/benchmarking_data_5000000.csv:
Traceback (most recent call last):
  File "/u/erg3kp/cylonplus/parallelpandas_testing/test/test_groupby.py", line 2, in <module>
    from parallel_pandas import ParallelPandas
  File "/u/erg3kp/.local/lib/python3.10/site-packages/parallel_pandas/__init__.py", line 1, in <module>
    from .main import ParallelPandas
  File "/u/erg3kp/.local/lib/python3.10/site-packages/parallel_pandas/main.py", line 3, in <module>
    from .core import series_parallelize_apply
  File "/u/erg3kp/.local/lib/python3.10/site-packages/parallel_pandas/core/__init__.py", line 4, in <module>
    from .parallel_dataframe import parallelize_apply
  File "/u/erg3kp/.local/lib/python3.10/site-packages/parallel_pandas/core/parallel_dataframe.py", line 22, in <module>
    from ._numba import _do_parallel_corr
  File "/u/erg3kp/.local/lib/python3.10/site-packages/parallel_pandas/core/_numba.py", line 4, in <module>
    from numba import njit, prange
  File "/sw/ubuntu-22.04/anaconda3/current/lib/python3.10/site-packages/numba/__init__.py", line 42, in <module>
    from numba.np.ufunc import (vectorize, guvectorize, threading_layer,
  File "/sw/ubuntu-22.04/anaconda3/current/lib/python3.10/site-packages/numba/np/ufunc/__init__.py", line 3, in <module>
    from numba.np.ufunc.decorators import Vectorize, GUVectorize, vectorize, guvectorize
  File "/sw/ubuntu-22.04/anaconda3/current/lib/python3.10/site-packages/numba/np/ufunc/decorators.py", line 3, in <module>
    from numba.np.ufunc import _internal
SystemError: initialization of _internal failed without raising an exception

Error running subprocess for test/test_groupby.py with ../data/benchmarking_data_varying_size/benchmarking_data_5000000.csv:
Traceback (most recent call last):
  File "/u/erg3kp/cylonplus/parallelpandas_testing/test/test_groupby.py", line 2, in <module>
    from parallel_pandas import ParallelPandas
  File "/u/erg3kp/.local/lib/python3.10/site-packages/parallel_pandas/__init__.py", line 1, in <module>
    from .main import ParallelPandas
  File "/u/erg3kp/.local/lib/python3.10/site-packages/parallel_pandas/main.py", line 3, in <module>
    from .core import series_parallelize_apply
  File "/u/erg3kp/.local/lib/python3.10/site-packages/parallel_pandas/core/__init__.py", line 4, in <module>
    from .parallel_dataframe import parallelize_apply
  File "/u/erg3kp/.local/lib/python3.10/site-packages/parallel_pandas/core/parallel_dataframe.py", line 22, in <module>
    from ._numba import _do_parallel_corr
  File "/u/erg3kp/.local/lib/python3.10/site-packages/parallel_pandas/core/_numba.py", line 4, in <module>
    from numba import njit, prange
  File "/sw/ubuntu-22.04/anaconda3/current/lib/python3.10/site-packages/numba/__init__.py", line 42, in <module>
    from numba.np.ufunc import (vectorize, guvectorize, threading_layer,
  File "/sw/ubuntu-22.04/anaconda3/current/lib/python3.10/site-packages/numba/np/ufunc/__init__.py", line 3, in <module>
    from numba.np.ufunc.decorators import Vectorize, GUVectorize, vectorize, guvectorize
  File "/sw/ubuntu-22.04/anaconda3/current/lib/python3.10/site-packages/numba/np/ufunc/decorators.py", line 3, in <module>
    from numba.np.ufunc import _internal
SystemError: initialization of _internal failed without raising an exception

Error running subprocess for test/test_groupby.py with ../data/benchmarking_data_varying_size/benchmarking_data_10000000.csv:
Traceback (most recent call last):
  File "/u/erg3kp/cylonplus/parallelpandas_testing/test/test_groupby.py", line 2, in <module>
    from parallel_pandas import ParallelPandas
  File "/u/erg3kp/.local/lib/python3.10/site-packages/parallel_pandas/__init__.py", line 1, in <module>
    from .main import ParallelPandas
  File "/u/erg3kp/.local/lib/python3.10/site-packages/parallel_pandas/main.py", line 3, in <module>
    from .core import series_parallelize_apply
  File "/u/erg3kp/.local/lib/python3.10/site-packages/parallel_pandas/core/__init__.py", line 4, in <module>
    from .parallel_dataframe import parallelize_apply
  File "/u/erg3kp/.local/lib/python3.10/site-packages/parallel_pandas/core/parallel_dataframe.py", line 22, in <module>
    from ._numba import _do_parallel_corr
  File "/u/erg3kp/.local/lib/python3.10/site-packages/parallel_pandas/core/_numba.py", line 4, in <module>
    from numba import njit, prange
  File "/sw/ubuntu-22.04/anaconda3/current/lib/python3.10/site-packages/numba/__init__.py", line 42, in <module>
    from numba.np.ufunc import (vectorize, guvectorize, threading_layer,
  File "/sw/ubuntu-22.04/anaconda3/current/lib/python3.10/site-packages/numba/np/ufunc/__init__.py", line 3, in <module>
    from numba.np.ufunc.decorators import Vectorize, GUVectorize, vectorize, guvectorize
  File "/sw/ubuntu-22.04/anaconda3/current/lib/python3.10/site-packages/numba/np/ufunc/decorators.py", line 3, in <module>
    from numba.np.ufunc import _internal
SystemError: initialization of _internal failed without raising an exception

Error running subprocess for test/test_groupby.py with ../data/benchmarking_data_varying_size/benchmarking_data_25000000.csv:
Traceback (most recent call last):
  File "/u/erg3kp/cylonplus/parallelpandas_testing/test/test_groupby.py", line 2, in <module>
    from parallel_pandas import ParallelPandas
  File "/u/erg3kp/.local/lib/python3.10/site-packages/parallel_pandas/__init__.py", line 1, in <module>
    from .main import ParallelPandas
  File "/u/erg3kp/.local/lib/python3.10/site-packages/parallel_pandas/main.py", line 3, in <module>
    from .core import series_parallelize_apply
  File "/u/erg3kp/.local/lib/python3.10/site-packages/parallel_pandas/core/__init__.py", line 4, in <module>
    from .parallel_dataframe import parallelize_apply
  File "/u/erg3kp/.local/lib/python3.10/site-packages/parallel_pandas/core/parallel_dataframe.py", line 22, in <module>
    from ._numba import _do_parallel_corr
  File "/u/erg3kp/.local/lib/python3.10/site-packages/parallel_pandas/core/_numba.py", line 4, in <module>
    from numba import njit, prange
  File "/sw/ubuntu-22.04/anaconda3/current/lib/python3.10/site-packages/numba/__init__.py", line 42, in <module>
    from numba.np.ufunc import (vectorize, guvectorize, threading_layer,
  File "/sw/ubuntu-22.04/anaconda3/current/lib/python3.10/site-packages/numba/np/ufunc/__init__.py", line 3, in <module>
    from numba.np.ufunc.decorators import Vectorize, GUVectorize, vectorize, guvectorize
  File "/sw/ubuntu-22.04/anaconda3/current/lib/python3.10/site-packages/numba/np/ufunc/decorators.py", line 3, in <module>
    from numba.np.ufunc import _internal
SystemError: initialization of _internal failed without raising an exception

Error running subprocess for test/test_groupby.py with ../data/benchmarking_data_varying_size/benchmarking_data_50000000.csv:
Traceback (most recent call last):
  File "/u/erg3kp/cylonplus/parallelpandas_testing/test/test_groupby.py", line 2, in <module>
    from parallel_pandas import ParallelPandas
  File "/u/erg3kp/.local/lib/python3.10/site-packages/parallel_pandas/__init__.py", line 1, in <module>
    from .main import ParallelPandas
  File "/u/erg3kp/.local/lib/python3.10/site-packages/parallel_pandas/main.py", line 3, in <module>
    from .core import series_parallelize_apply
  File "/u/erg3kp/.local/lib/python3.10/site-packages/parallel_pandas/core/__init__.py", line 4, in <module>
    from .parallel_dataframe import parallelize_apply
  File "/u/erg3kp/.local/lib/python3.10/site-packages/parallel_pandas/core/parallel_dataframe.py", line 22, in <module>
    from ._numba import _do_parallel_corr
  File "/u/erg3kp/.local/lib/python3.10/site-packages/parallel_pandas/core/_numba.py", line 4, in <module>
    from numba import njit, prange
  File "/sw/ubuntu-22.04/anaconda3/current/lib/python3.10/site-packages/numba/__init__.py", line 42, in <module>
    from numba.np.ufunc import (vectorize, guvectorize, threading_layer,
  File "/sw/ubuntu-22.04/anaconda3/current/lib/python3.10/site-packages/numba/np/ufunc/__init__.py", line 3, in <module>
    from numba.np.ufunc.decorators import Vectorize, GUVectorize, vectorize, guvectorize
  File "/sw/ubuntu-22.04/anaconda3/current/lib/python3.10/site-packages/numba/np/ufunc/decorators.py", line 3, in <module>
    from numba.np.ufunc import _internal
SystemError: initialization of _internal failed without raising an exception

Error running subprocess for test/test_groupby.py with ../data/benchmarking_data_varying_size/benchmarking_data_75000000.csv:
Traceback (most recent call last):
  File "/u/erg3kp/cylonplus/parallelpandas_testing/test/test_groupby.py", line 2, in <module>
    from parallel_pandas import ParallelPandas
  File "/u/erg3kp/.local/lib/python3.10/site-packages/parallel_pandas/__init__.py", line 1, in <module>
    from .main import ParallelPandas
  File "/u/erg3kp/.local/lib/python3.10/site-packages/parallel_pandas/main.py", line 3, in <module>
    from .core import series_parallelize_apply
  File "/u/erg3kp/.local/lib/python3.10/site-packages/parallel_pandas/core/__init__.py", line 4, in <module>
    from .parallel_dataframe import parallelize_apply
  File "/u/erg3kp/.local/lib/python3.10/site-packages/parallel_pandas/core/parallel_dataframe.py", line 22, in <module>
    from ._numba import _do_parallel_corr
  File "/u/erg3kp/.local/lib/python3.10/site-packages/parallel_pandas/core/_numba.py", line 4, in <module>
    from numba import njit, prange
  File "/sw/ubuntu-22.04/anaconda3/current/lib/python3.10/site-packages/numba/__init__.py", line 42, in <module>
    from numba.np.ufunc import (vectorize, guvectorize, threading_layer,
  File "/sw/ubuntu-22.04/anaconda3/current/lib/python3.10/site-packages/numba/np/ufunc/__init__.py", line 3, in <module>
    from numba.np.ufunc.decorators import Vectorize, GUVectorize, vectorize, guvectorize
  File "/sw/ubuntu-22.04/anaconda3/current/lib/python3.10/site-packages/numba/np/ufunc/decorators.py", line 3, in <module>
    from numba.np.ufunc import _internal
SystemError: initialization of _internal failed without raising an exception

Error running subprocess for test/test_groupby.py with ../data/benchmarking_data_varying_size/benchmarking_data_100000000.csv:
Traceback (most recent call last):
  File "/u/erg3kp/cylonplus/parallelpandas_testing/test/test_groupby.py", line 2, in <module>
    from parallel_pandas import ParallelPandas
  File "/u/erg3kp/.local/lib/python3.10/site-packages/parallel_pandas/__init__.py", line 1, in <module>
    from .main import ParallelPandas
  File "/u/erg3kp/.local/lib/python3.10/site-packages/parallel_pandas/main.py", line 3, in <module>
    from .core import series_parallelize_apply
  File "/u/erg3kp/.local/lib/python3.10/site-packages/parallel_pandas/core/__init__.py", line 4, in <module>
    from .parallel_dataframe import parallelize_apply
  File "/u/erg3kp/.local/lib/python3.10/site-packages/parallel_pandas/core/parallel_dataframe.py", line 22, in <module>
    from ._numba import _do_parallel_corr
  File "/u/erg3kp/.local/lib/python3.10/site-packages/parallel_pandas/core/_numba.py", line 4, in <module>
    from numba import njit, prange
  File "/sw/ubuntu-22.04/anaconda3/current/lib/python3.10/site-packages/numba/__init__.py", line 42, in <module>
    from numba.np.ufunc import (vectorize, guvectorize, threading_layer,
  File "/sw/ubuntu-22.04/anaconda3/current/lib/python3.10/site-packages/numba/np/ufunc/__init__.py", line 3, in <module>
    from numba.np.ufunc.decorators import Vectorize, GUVectorize, vectorize, guvectorize
  File "/sw/ubuntu-22.04/anaconda3/current/lib/python3.10/site-packages/numba/np/ufunc/decorators.py", line 3, in <module>
    from numba.np.ufunc import _internal
SystemError: initialization of _internal failed without raising an exception

Test Finished
Running tests for test/test_io.py with argument (if needed): ...
Error running subprocess for test/test_io.py with ../data/benchmarking_data_varying_size/benchmarking_data_10000.csv:
Traceback (most recent call last):
  File "/u/erg3kp/cylonplus/parallelpandas_testing/test/test_io.py", line 3, in <module>
    from parallel_pandas import ParallelPandas
  File "/u/erg3kp/.local/lib/python3.10/site-packages/parallel_pandas/__init__.py", line 1, in <module>
    from .main import ParallelPandas
  File "/u/erg3kp/.local/lib/python3.10/site-packages/parallel_pandas/main.py", line 3, in <module>
    from .core import series_parallelize_apply
  File "/u/erg3kp/.local/lib/python3.10/site-packages/parallel_pandas/core/__init__.py", line 4, in <module>
    from .parallel_dataframe import parallelize_apply
  File "/u/erg3kp/.local/lib/python3.10/site-packages/parallel_pandas/core/parallel_dataframe.py", line 22, in <module>
    from ._numba import _do_parallel_corr
  File "/u/erg3kp/.local/lib/python3.10/site-packages/parallel_pandas/core/_numba.py", line 4, in <module>
    from numba import njit, prange
  File "/sw/ubuntu-22.04/anaconda3/current/lib/python3.10/site-packages/numba/__init__.py", line 42, in <module>
    from numba.np.ufunc import (vectorize, guvectorize, threading_layer,
  File "/sw/ubuntu-22.04/anaconda3/current/lib/python3.10/site-packages/numba/np/ufunc/__init__.py", line 3, in <module>
    from numba.np.ufunc.decorators import Vectorize, GUVectorize, vectorize, guvectorize
  File "/sw/ubuntu-22.04/anaconda3/current/lib/python3.10/site-packages/numba/np/ufunc/decorators.py", line 3, in <module>
    from numba.np.ufunc import _internal
SystemError: initialization of _internal failed without raising an exception

Error running subprocess for test/test_io.py with ../data/benchmarking_data_varying_size/benchmarking_data_500000.csv:
Traceback (most recent call last):
  File "/u/erg3kp/cylonplus/parallelpandas_testing/test/test_io.py", line 3, in <module>
    from parallel_pandas import ParallelPandas
  File "/u/erg3kp/.local/lib/python3.10/site-packages/parallel_pandas/__init__.py", line 1, in <module>
    from .main import ParallelPandas
  File "/u/erg3kp/.local/lib/python3.10/site-packages/parallel_pandas/main.py", line 3, in <module>
    from .core import series_parallelize_apply
  File "/u/erg3kp/.local/lib/python3.10/site-packages/parallel_pandas/core/__init__.py", line 4, in <module>
    from .parallel_dataframe import parallelize_apply
  File "/u/erg3kp/.local/lib/python3.10/site-packages/parallel_pandas/core/parallel_dataframe.py", line 22, in <module>
    from ._numba import _do_parallel_corr
  File "/u/erg3kp/.local/lib/python3.10/site-packages/parallel_pandas/core/_numba.py", line 4, in <module>
    from numba import njit, prange
  File "/sw/ubuntu-22.04/anaconda3/current/lib/python3.10/site-packages/numba/__init__.py", line 42, in <module>
    from numba.np.ufunc import (vectorize, guvectorize, threading_layer,
  File "/sw/ubuntu-22.04/anaconda3/current/lib/python3.10/site-packages/numba/np/ufunc/__init__.py", line 3, in <module>
    from numba.np.ufunc.decorators import Vectorize, GUVectorize, vectorize, guvectorize
  File "/sw/ubuntu-22.04/anaconda3/current/lib/python3.10/site-packages/numba/np/ufunc/decorators.py", line 3, in <module>
    from numba.np.ufunc import _internal
SystemError: initialization of _internal failed without raising an exception

Error running subprocess for test/test_io.py with ../data/benchmarking_data_varying_size/benchmarking_data_1000000.csv:
Traceback (most recent call last):
  File "/u/erg3kp/cylonplus/parallelpandas_testing/test/test_io.py", line 3, in <module>
    from parallel_pandas import ParallelPandas
  File "/u/erg3kp/.local/lib/python3.10/site-packages/parallel_pandas/__init__.py", line 1, in <module>
    from .main import ParallelPandas
  File "/u/erg3kp/.local/lib/python3.10/site-packages/parallel_pandas/main.py", line 3, in <module>
    from .core import series_parallelize_apply
  File "/u/erg3kp/.local/lib/python3.10/site-packages/parallel_pandas/core/__init__.py", line 4, in <module>
    from .parallel_dataframe import parallelize_apply
  File "/u/erg3kp/.local/lib/python3.10/site-packages/parallel_pandas/core/parallel_dataframe.py", line 22, in <module>
    from ._numba import _do_parallel_corr
  File "/u/erg3kp/.local/lib/python3.10/site-packages/parallel_pandas/core/_numba.py", line 4, in <module>
    from numba import njit, prange
  File "/sw/ubuntu-22.04/anaconda3/current/lib/python3.10/site-packages/numba/__init__.py", line 42, in <module>
    from numba.np.ufunc import (vectorize, guvectorize, threading_layer,
  File "/sw/ubuntu-22.04/anaconda3/current/lib/python3.10/site-packages/numba/np/ufunc/__init__.py", line 3, in <module>
    from numba.np.ufunc.decorators import Vectorize, GUVectorize, vectorize, guvectorize
  File "/sw/ubuntu-22.04/anaconda3/current/lib/python3.10/site-packages/numba/np/ufunc/decorators.py", line 3, in <module>
    from numba.np.ufunc import _internal
SystemError: initialization of _internal failed without raising an exception

Error running subprocess for test/test_io.py with ../data/benchmarking_data_varying_size/benchmarking_data_2500000.csv:
Traceback (most recent call last):
  File "/u/erg3kp/cylonplus/parallelpandas_testing/test/test_io.py", line 3, in <module>
    from parallel_pandas import ParallelPandas
  File "/u/erg3kp/.local/lib/python3.10/site-packages/parallel_pandas/__init__.py", line 1, in <module>
    from .main import ParallelPandas
  File "/u/erg3kp/.local/lib/python3.10/site-packages/parallel_pandas/main.py", line 3, in <module>
    from .core import series_parallelize_apply
  File "/u/erg3kp/.local/lib/python3.10/site-packages/parallel_pandas/core/__init__.py", line 4, in <module>
    from .parallel_dataframe import parallelize_apply
  File "/u/erg3kp/.local/lib/python3.10/site-packages/parallel_pandas/core/parallel_dataframe.py", line 22, in <module>
    from ._numba import _do_parallel_corr
  File "/u/erg3kp/.local/lib/python3.10/site-packages/parallel_pandas/core/_numba.py", line 4, in <module>
    from numba import njit, prange
  File "/sw/ubuntu-22.04/anaconda3/current/lib/python3.10/site-packages/numba/__init__.py", line 42, in <module>
    from numba.np.ufunc import (vectorize, guvectorize, threading_layer,
  File "/sw/ubuntu-22.04/anaconda3/current/lib/python3.10/site-packages/numba/np/ufunc/__init__.py", line 3, in <module>
    from numba.np.ufunc.decorators import Vectorize, GUVectorize, vectorize, guvectorize
  File "/sw/ubuntu-22.04/anaconda3/current/lib/python3.10/site-packages/numba/np/ufunc/decorators.py", line 3, in <module>
    from numba.np.ufunc import _internal
SystemError: initialization of _internal failed without raising an exception

Error running subprocess for test/test_io.py with ../data/benchmarking_data_varying_size/benchmarking_data_5000000.csv:
Traceback (most recent call last):
  File "/u/erg3kp/cylonplus/parallelpandas_testing/test/test_io.py", line 3, in <module>
    from parallel_pandas import ParallelPandas
  File "/u/erg3kp/.local/lib/python3.10/site-packages/parallel_pandas/__init__.py", line 1, in <module>
    from .main import ParallelPandas
  File "/u/erg3kp/.local/lib/python3.10/site-packages/parallel_pandas/main.py", line 3, in <module>
    from .core import series_parallelize_apply
  File "/u/erg3kp/.local/lib/python3.10/site-packages/parallel_pandas/core/__init__.py", line 4, in <module>
    from .parallel_dataframe import parallelize_apply
  File "/u/erg3kp/.local/lib/python3.10/site-packages/parallel_pandas/core/parallel_dataframe.py", line 22, in <module>
    from ._numba import _do_parallel_corr
  File "/u/erg3kp/.local/lib/python3.10/site-packages/parallel_pandas/core/_numba.py", line 4, in <module>
    from numba import njit, prange
  File "/sw/ubuntu-22.04/anaconda3/current/lib/python3.10/site-packages/numba/__init__.py", line 42, in <module>
    from numba.np.ufunc import (vectorize, guvectorize, threading_layer,
  File "/sw/ubuntu-22.04/anaconda3/current/lib/python3.10/site-packages/numba/np/ufunc/__init__.py", line 3, in <module>
    from numba.np.ufunc.decorators import Vectorize, GUVectorize, vectorize, guvectorize
  File "/sw/ubuntu-22.04/anaconda3/current/lib/python3.10/site-packages/numba/np/ufunc/decorators.py", line 3, in <module>
    from numba.np.ufunc import _internal
SystemError: initialization of _internal failed without raising an exception

Error running subprocess for test/test_io.py with ../data/benchmarking_data_varying_size/benchmarking_data_5000000.csv:
Traceback (most recent call last):
  File "/u/erg3kp/cylonplus/parallelpandas_testing/test/test_io.py", line 3, in <module>
    from parallel_pandas import ParallelPandas
  File "/u/erg3kp/.local/lib/python3.10/site-packages/parallel_pandas/__init__.py", line 1, in <module>
    from .main import ParallelPandas
  File "/u/erg3kp/.local/lib/python3.10/site-packages/parallel_pandas/main.py", line 3, in <module>
    from .core import series_parallelize_apply
  File "/u/erg3kp/.local/lib/python3.10/site-packages/parallel_pandas/core/__init__.py", line 4, in <module>
    from .parallel_dataframe import parallelize_apply
  File "/u/erg3kp/.local/lib/python3.10/site-packages/parallel_pandas/core/parallel_dataframe.py", line 22, in <module>
    from ._numba import _do_parallel_corr
  File "/u/erg3kp/.local/lib/python3.10/site-packages/parallel_pandas/core/_numba.py", line 4, in <module>
    from numba import njit, prange
  File "/sw/ubuntu-22.04/anaconda3/current/lib/python3.10/site-packages/numba/__init__.py", line 42, in <module>
    from numba.np.ufunc import (vectorize, guvectorize, threading_layer,
  File "/sw/ubuntu-22.04/anaconda3/current/lib/python3.10/site-packages/numba/np/ufunc/__init__.py", line 3, in <module>
    from numba.np.ufunc.decorators import Vectorize, GUVectorize, vectorize, guvectorize
  File "/sw/ubuntu-22.04/anaconda3/current/lib/python3.10/site-packages/numba/np/ufunc/decorators.py", line 3, in <module>
    from numba.np.ufunc import _internal
SystemError: initialization of _internal failed without raising an exception

Error running subprocess for test/test_io.py with ../data/benchmarking_data_varying_size/benchmarking_data_10000000.csv:
Traceback (most recent call last):
  File "/u/erg3kp/cylonplus/parallelpandas_testing/test/test_io.py", line 3, in <module>
    from parallel_pandas import ParallelPandas
  File "/u/erg3kp/.local/lib/python3.10/site-packages/parallel_pandas/__init__.py", line 1, in <module>
    from .main import ParallelPandas
  File "/u/erg3kp/.local/lib/python3.10/site-packages/parallel_pandas/main.py", line 3, in <module>
    from .core import series_parallelize_apply
  File "/u/erg3kp/.local/lib/python3.10/site-packages/parallel_pandas/core/__init__.py", line 4, in <module>
    from .parallel_dataframe import parallelize_apply
  File "/u/erg3kp/.local/lib/python3.10/site-packages/parallel_pandas/core/parallel_dataframe.py", line 22, in <module>
    from ._numba import _do_parallel_corr
  File "/u/erg3kp/.local/lib/python3.10/site-packages/parallel_pandas/core/_numba.py", line 4, in <module>
    from numba import njit, prange
  File "/sw/ubuntu-22.04/anaconda3/current/lib/python3.10/site-packages/numba/__init__.py", line 42, in <module>
    from numba.np.ufunc import (vectorize, guvectorize, threading_layer,
  File "/sw/ubuntu-22.04/anaconda3/current/lib/python3.10/site-packages/numba/np/ufunc/__init__.py", line 3, in <module>
    from numba.np.ufunc.decorators import Vectorize, GUVectorize, vectorize, guvectorize
  File "/sw/ubuntu-22.04/anaconda3/current/lib/python3.10/site-packages/numba/np/ufunc/decorators.py", line 3, in <module>
    from numba.np.ufunc import _internal
SystemError: initialization of _internal failed without raising an exception

Error running subprocess for test/test_io.py with ../data/benchmarking_data_varying_size/benchmarking_data_25000000.csv:
Traceback (most recent call last):
  File "/u/erg3kp/cylonplus/parallelpandas_testing/test/test_io.py", line 3, in <module>
    from parallel_pandas import ParallelPandas
  File "/u/erg3kp/.local/lib/python3.10/site-packages/parallel_pandas/__init__.py", line 1, in <module>
    from .main import ParallelPandas
  File "/u/erg3kp/.local/lib/python3.10/site-packages/parallel_pandas/main.py", line 3, in <module>
    from .core import series_parallelize_apply
  File "/u/erg3kp/.local/lib/python3.10/site-packages/parallel_pandas/core/__init__.py", line 4, in <module>
    from .parallel_dataframe import parallelize_apply
  File "/u/erg3kp/.local/lib/python3.10/site-packages/parallel_pandas/core/parallel_dataframe.py", line 22, in <module>
    from ._numba import _do_parallel_corr
  File "/u/erg3kp/.local/lib/python3.10/site-packages/parallel_pandas/core/_numba.py", line 4, in <module>
    from numba import njit, prange
  File "/sw/ubuntu-22.04/anaconda3/current/lib/python3.10/site-packages/numba/__init__.py", line 42, in <module>
    from numba.np.ufunc import (vectorize, guvectorize, threading_layer,
  File "/sw/ubuntu-22.04/anaconda3/current/lib/python3.10/site-packages/numba/np/ufunc/__init__.py", line 3, in <module>
    from numba.np.ufunc.decorators import Vectorize, GUVectorize, vectorize, guvectorize
  File "/sw/ubuntu-22.04/anaconda3/current/lib/python3.10/site-packages/numba/np/ufunc/decorators.py", line 3, in <module>
    from numba.np.ufunc import _internal
SystemError: initialization of _internal failed without raising an exception

Error running subprocess for test/test_io.py with ../data/benchmarking_data_varying_size/benchmarking_data_50000000.csv:
Traceback (most recent call last):
  File "/u/erg3kp/cylonplus/parallelpandas_testing/test/test_io.py", line 3, in <module>
    from parallel_pandas import ParallelPandas
  File "/u/erg3kp/.local/lib/python3.10/site-packages/parallel_pandas/__init__.py", line 1, in <module>
    from .main import ParallelPandas
  File "/u/erg3kp/.local/lib/python3.10/site-packages/parallel_pandas/main.py", line 3, in <module>
    from .core import series_parallelize_apply
  File "/u/erg3kp/.local/lib/python3.10/site-packages/parallel_pandas/core/__init__.py", line 4, in <module>
    from .parallel_dataframe import parallelize_apply
  File "/u/erg3kp/.local/lib/python3.10/site-packages/parallel_pandas/core/parallel_dataframe.py", line 22, in <module>
    from ._numba import _do_parallel_corr
  File "/u/erg3kp/.local/lib/python3.10/site-packages/parallel_pandas/core/_numba.py", line 4, in <module>
    from numba import njit, prange
  File "/sw/ubuntu-22.04/anaconda3/current/lib/python3.10/site-packages/numba/__init__.py", line 42, in <module>
    from numba.np.ufunc import (vectorize, guvectorize, threading_layer,
  File "/sw/ubuntu-22.04/anaconda3/current/lib/python3.10/site-packages/numba/np/ufunc/__init__.py", line 3, in <module>
    from numba.np.ufunc.decorators import Vectorize, GUVectorize, vectorize, guvectorize
  File "/sw/ubuntu-22.04/anaconda3/current/lib/python3.10/site-packages/numba/np/ufunc/decorators.py", line 3, in <module>
    from numba.np.ufunc import _internal
SystemError: initialization of _internal failed without raising an exception

Error running subprocess for test/test_io.py with ../data/benchmarking_data_varying_size/benchmarking_data_75000000.csv:
Traceback (most recent call last):
  File "/u/erg3kp/cylonplus/parallelpandas_testing/test/test_io.py", line 3, in <module>
    from parallel_pandas import ParallelPandas
  File "/u/erg3kp/.local/lib/python3.10/site-packages/parallel_pandas/__init__.py", line 1, in <module>
    from .main import ParallelPandas
  File "/u/erg3kp/.local/lib/python3.10/site-packages/parallel_pandas/main.py", line 3, in <module>
    from .core import series_parallelize_apply
  File "/u/erg3kp/.local/lib/python3.10/site-packages/parallel_pandas/core/__init__.py", line 4, in <module>
    from .parallel_dataframe import parallelize_apply
  File "/u/erg3kp/.local/lib/python3.10/site-packages/parallel_pandas/core/parallel_dataframe.py", line 22, in <module>
    from ._numba import _do_parallel_corr
  File "/u/erg3kp/.local/lib/python3.10/site-packages/parallel_pandas/core/_numba.py", line 4, in <module>
    from numba import njit, prange
  File "/sw/ubuntu-22.04/anaconda3/current/lib/python3.10/site-packages/numba/__init__.py", line 42, in <module>
    from numba.np.ufunc import (vectorize, guvectorize, threading_layer,
  File "/sw/ubuntu-22.04/anaconda3/current/lib/python3.10/site-packages/numba/np/ufunc/__init__.py", line 3, in <module>
    from numba.np.ufunc.decorators import Vectorize, GUVectorize, vectorize, guvectorize
  File "/sw/ubuntu-22.04/anaconda3/current/lib/python3.10/site-packages/numba/np/ufunc/decorators.py", line 3, in <module>
    from numba.np.ufunc import _internal
SystemError: initialization of _internal failed without raising an exception

Error running subprocess for test/test_io.py with ../data/benchmarking_data_varying_size/benchmarking_data_100000000.csv:
Traceback (most recent call last):
  File "/u/erg3kp/cylonplus/parallelpandas_testing/test/test_io.py", line 3, in <module>
    from parallel_pandas import ParallelPandas
  File "/u/erg3kp/.local/lib/python3.10/site-packages/parallel_pandas/__init__.py", line 1, in <module>
    from .main import ParallelPandas
  File "/u/erg3kp/.local/lib/python3.10/site-packages/parallel_pandas/main.py", line 3, in <module>
    from .core import series_parallelize_apply
  File "/u/erg3kp/.local/lib/python3.10/site-packages/parallel_pandas/core/__init__.py", line 4, in <module>
    from .parallel_dataframe import parallelize_apply
  File "/u/erg3kp/.local/lib/python3.10/site-packages/parallel_pandas/core/parallel_dataframe.py", line 22, in <module>
    from ._numba import _do_parallel_corr
  File "/u/erg3kp/.local/lib/python3.10/site-packages/parallel_pandas/core/_numba.py", line 4, in <module>
    from numba import njit, prange
  File "/sw/ubuntu-22.04/anaconda3/current/lib/python3.10/site-packages/numba/__init__.py", line 42, in <module>
    from numba.np.ufunc import (vectorize, guvectorize, threading_layer,
  File "/sw/ubuntu-22.04/anaconda3/current/lib/python3.10/site-packages/numba/np/ufunc/__init__.py", line 3, in <module>
    from numba.np.ufunc.decorators import Vectorize, GUVectorize, vectorize, guvectorize
  File "/sw/ubuntu-22.04/anaconda3/current/lib/python3.10/site-packages/numba/np/ufunc/decorators.py", line 3, in <module>
    from numba.np.ufunc import _internal
SystemError: initialization of _internal failed without raising an exception

Test Finished
All Tests Finished
Traceback (most recent call last):
  File "/u/erg3kp/cylonplus/parallelpandas_testing/graph_tests.py", line 109, in <module>
    smoothed_times = np.convolve(times, np.ones(3)/3, mode='valid')
  File "/u/erg3kp/.local/lib/python3.10/site-packages/numpy/core/numeric.py", line 833, in convolve
    raise ValueError('v cannot be empty')
ValueError: v cannot be empty
